### 主要使用try，catch,throw语句

```cpp
try{
    //可能出现错误的代码段
}
catch(const std::invalid_argument& e){
     std::cerr << "Error: " << e.what() << std::endl;
}
```

```cpp
在可能出现错误的代码段中，如果有throw,例如
void divide(double a, double b) {
    if (b == 0) {
        throw std::invalid_argument("Division by zero"); // 抛出异常
    }
    std::cout << "Result: " << a / b << std::endl;
}
```
则会立即跳转到匹配的catch语句执行

### 捕获的异常类型
1. 特定的类型
**例如std::invalid_argument** 
2. 所有标准异常
**例如std::exception**